Workbook

Sheet Mode d'emploi
B1: Saisie des prix de vente
B2: Comptoir des Chatonniers — 702 produits issus de la base fournisseurs 2026
B4: Nouveau : les prix sont préremplis
B5: Les 701 prix de vente proposés par coefficients de marché sont déjà dans la colonne PRIX DE VENTE HT, avec le statut PROPOSÉ. Votre travail n'est plus de saisir 700 prix : c'est de les relire, corriger ceux qui tombent à côté, et passer le statut à VALIDÉ. Un prix non validé reste une hypothèse de travail.
B7: Ce qu'il faut remplir
B8: Trois colonnes seulement, surlignées en jaune dans l'onglet « Prix de vente » :
B9: • PRIX DE VENTE HT — le prix auquel vous vendez le produit dans un coffret.
B10: • CATALOGUE SAISON — OUI si vous retenez le produit pour la saison en cours.
B11: • NOTES — vos remarques (produit à revoir, fournisseur à rappeler…).
B12: Tout le reste est calculé automatiquement : marge, taux de marge, coefficient, prix TTC.
B14: Ne saisissez pas les 702 prix
B15: Commencez par le catalogue de saison : 120 à 200 références que vous savez pouvoir obtenir. Mettez OUI dans la colonne CATALOGUE SAISON, puis ne saisissez le prix que pour celles-là. Le moteur de composition n'a besoin que de produits fiables, pas de tous les produits.
... B32: Enregistrez le fichier sans changer son nom ni l'ordre des colonnes, et renvoyez-le. Il se réimporte tel quel dans la base de données.

Sheet Prix de vente
A1: ID | B1: PRODUIT | C1: CATÉGORIE | D1: SOUS-CATÉGORIE | E1: GAMME | F1: PRODUCTEUR | G1: FOURNISSEUR | H1: CONDITIONNEMENT | I1: POIDS/VOL. | J1: ALCOOL | K1: TVA | L1: PRIX ACHAT HT | M1: PRIX DE VENTE HT | N1: STATUT PRIX | O1: MARGE € | P1: TAUX DE MARGE | Q1: COEFF. | R1: PRIX VENTE TTC | S1: CATALOGUE SAISON | T1: NOTES
A2: PROD-0396 | B2: Pinte 50 cl Brasserie Lalie | C2: ART_DE_LA_TABLE_ET_OBJET | D2: OBJET_ET_CONTENANT | E2: ESSENTIEL | F2: BRASSERIE LA LIE | G2: NORMAND DIRECT TERROIR | I2: 500 ml | J2: NON | K2: 20 % | L2: 2.38 | M2: 6 | N2: PROPOSÉ | O2: =IF(M2="","",M2-L2) | P2: =IF(OR(M2="",M2=0),"",(M2-L2)/M2) | Q2: =IF(OR(M2="",L2=0,L2=""),"",M2/L2) | R2: =IF(M2="","",M2*1.2)
A3: PROD-0397 | B3: Verre à bière Brasserie Lalie 25 cl | C3: ART_DE_LA_TABLE_ET_OBJET | D3: OBJET_ET_CONTENANT | E3: ESSENTIEL | F3: BRASSERIE LA LIE | G3: NORMAND DIRECT TERROIR | I3: 250 ml | J3: NON | K3: 20 % | L3: 2.1 | M3: 5.3 | N3: PROPOSÉ | O3: =IF(M3="","",M3-L3) | P3: =IF(OR(M3="",M3=0),"",(M3-L3)/M3) | Q3: =IF(OR(M3="",L3=0,L3=""),"",M3/L3) | R3: =IF(M3="","",M3*1.2)
A4: PROD-0657 | B4: PRÉSENTOIR POUR 100 SUCETTES | C4: ART_DE_LA_TABLE_ET_OBJET | D4: OBJET_ET_CONTENANT | E4: SIGNATURE | F4: CARAMELS D'ISIGNY | G4: CARAMELS D'ISIGNY | H4: 225G | I4: 225 g | J4: NON | K4: 20 % | L4: 8.38 | M4: 17.7 | N4: PROPOSÉ | O4: =IF(M4="","",M4-L4) | P4: =IF(OR(M4="",M4=0),"",(M4-L4)/M4) | Q4: =IF(OR(M4="",L4=0,L4=""),"",M4/L4) | R4: =IF(M4="","",M4*1.2)
A5: PROD-0018 | B5: Financiers boite 250 grs | C5: BISCUITERIE | D5: BISCUIT | E5: ESSENTIEL | F5: BISCUITERIE DE QUINEVILLE | G5: NORMAND DIRECT TERROIR | I5: 250 g | J5: NON | K5: 5.5 % | L5: 4.9 | M5: 11.8 | N5: PROPOSÉ | O5: =IF(M5="","",M5-L5) | P5: =IF(OR(M5="",M5=0),"",(M5-L5)/M5) | Q5: =IF(OR(M5="",L5=0,L5=""),"",M5/L5) | R5: =IF(M5="","",M5*1.055)
A6: PROD-0013 | B6: Croquenoisette chocolat 180 grs | C6: BISCUITERIE | D6: BISCUIT | E6: ESSENTIEL | F6: BISCUITERIE DE QUINEVILLE | G6: NORMAND DIRECT TERROIR | I6: 180 g | J6: NON | K6: 5.5 % | L6: 4.55 | M6: 10.9 | N6: PROPOSÉ | O6: =IF(M6="","",M6-L6) | P6: =IF(OR(M6="",M6=0),"",(M6-L6)/M6) | Q6: =IF(OR(M6="",L6=0,L6=""),"",M6/L6) | R6: =IF(M6="","",M6*1.055)
A7: PROD-0020 | B7: Sablé chocolat enrobage chocolat lait 180 grs | C7: BISCUITERIE | D7: BISCUIT | E7: ESSENTIEL | F7: BISCUITERIE DE QUINEVILLE | G7: NORMAND DIRECT TERROIR | I7: 180 g | J7: NON | K7: 5.5 % | L7: 4.5 | M7: 10.8 | N7: PROPOSÉ | O7: =IF(M7="","",M7-L7) | P7: =IF(OR(M7="",M7=0),"",(M7-L7)/M7) | Q7: =IF(OR(M7="",L7=0,L7=""),"",M7/L7) | R7: =IF(M7="","",M7*1.055)
A8: PROD-0008 | B8: Coquilles Quinéville 165 grs | C8: BISCUITERIE | D8: BISCUIT | E8: ESSENTIEL | F8: BISCUITERIE DE QUINEVILLE | G8: NORMAND DIRECT TERROIR | I8: 165 g | J8: NON | K8: 5.5 % | L8: 4.37 | M8: 10.5 | N8: PROPOSÉ | O8: =IF(M8="","",M8-L8) | P8: =IF(OR(M8="",M8=0),"",(M8-L8)/M8) | Q8: =IF(OR(M8="",L8=0,L8=""),"",M8/L8) | R8: =IF(M8="","",M8*1.055)
A9: PROD-0010 | B9: Coquilles de Quinéville trio 165 grs | C9: BISCUITERIE | D9: BISCUIT | E9: ESSENTIEL | F9: BISCUITERIE DE QUINEVILLE | G9: NORMAND DIRECT TERROIR | I9: 165 g | J9: NON | K9: 5.5 % | L9: 4.37 | M9: 10.5 | N9: PROPOSÉ | O9: =IF(M9="","",M9-L9) | P9: =IF(OR(M9="",M9=0),"",(M9-L9)/M9) | Q9: =IF(OR(M9="",L9=0,L9=""),"",M9/L9) | R9: =IF(M9="","",M9*1.055)
A10: PROD-0012 | B10: Croquant aux amandes 125 grs | C10: BISCUITERIE | D10: BISCUIT | E10: ESSENTIEL | F10: BISCUITERIE DE QUINEVILLE | G10: NORMAND DIRECT TERROIR | I10: 125 g | J10: NON | K10: 5.5 % | L10: 4.3 | M10: 10.3 | N10: PROPOSÉ | O10: =IF(M10="","",M10-L10) | P10: =IF(OR(M10="",M10=0),"",(M10-L10)/M10) | Q10: =IF(OR(M10="",L10=0,L10=""),"",M10/L10) | R10: =IF(M10="","",M10*1.055)
A11: PROD-0658 | B11: COOKIES AUX ÉCLATS DE CARAMEL | C11: BISCUITERIE | D11: BISCUIT | E11: ESSENTIEL | F11: CARAMELS D'ISIGNY | G11: CARAMELS D'ISIGNY | H11: 220G | I11: 220 g | J11: NON | K11: 5.5 % | L11: 4.16 | M11: 10 | N11: PROPOSÉ | O11: =IF(M11="","",M11-L11) | P11: =IF(OR(M11="",M11=0),"",(M11-L11)/M11) | Q11: =IF(OR(M11="",L11=0,L11=""),"",M11/L11) | R11: =IF(M11="","",M11*1.055)
A12: PROD-0023 | B12: Sablé spéculos 250 grs | C12: BISCUITERIE | D12: BISCUIT | E12: ESSENTIEL | F12: BISCUITERIE DE QUINEVILLE | G12: NORMAND DIRECT TERROIR | I12: 250 g | J12: NON | K12: 5.5 % | L12: 3.95 | M12: 9.5 | N12: PROPOSÉ | O12: =IF(M12="","",M12-L12) | P12: =IF(OR(M12="",M12=0),"",(M12-L12)/M12) | Q12: =IF(OR(M12="",L12=0,L12=""),"",M12/L12) | R12: =IF(M12="","",M12*1.055)
A13: PROD-0454 | B13: Pain D'épices aux pépites de Chocolats 250gr | C13: BISCUITERIE | D13: BISCUIT | E13: ESSENTIEL | F13: Rucher du bocage Virois | G13: NORMAND DIRECT TERROIR | H13: Barquette en bois | I13: 250 g | J13: NON | K13: 5.5 % | L13: 3.95 | M13: 9.5 | N13: PROPOSÉ | O13: =IF(M13="","",M13-L13) | P13: =IF(OR(M13="",M13=0),"",(M13-L13)/M13) | Q13: =IF(OR(M13="",L13=0,L13=""),"",M13/L13) | R13: =IF(M13="","",M13*1.055)
A14: PROD-0455 | B14: Pain D'épices aux éclats de Noix 250gr | C14: BISCUITERIE | D14: BISCUIT | E14: ESSENTIEL | F14: Rucher du bocage Virois | G14: NORMAND DIRECT TERROIR | H14: Barquette en bois | I14: 250 g | J14: NON | K14: 5.5 % | L14: 3.95 | M14: 9.5 | N14: PROPOSÉ | O14: =IF(M14="","",M14-L14) | P14: =IF(OR(M14="",M14=0),"",(M14-L14)/M14) | Q14: =IF(OR(M14="",L14=0,L14=""),"",M14/L14) | R14: =IF(M14="","",M14*1.055)
A15: PROD-0456 | B15: Pain D'épices aux écorces d'Oranges 250gr | C15: BISCUITERIE | D15: BISCUIT | E15: ESSENTIEL | F15: Rucher du bocage Virois | G15: NORMAND DIRECT TERROIR | H15: Barquette en bois | I15: 250 g | J15: NON | K15: 5.5 % | L15: 3.95 | M15: 9.5 | N15: PROPOSÉ | O15: =IF(M15="","",M15-L15) | P15: =IF(OR(M15="",M15=0),"",(M15-L15)/M15) | Q15: =IF(OR(M15="",L15=0,L15=""),"",M15/L15) | R15: =IF(M15="","",M15*1.055)
A16: PROD-0457 | B16: Pain D'épices aux Figues 250gr (fin d'année) | C16: BISCUITERIE | D16: BISCUIT | E16: ESSENTIEL | F16: Rucher du bocage Virois | G16: NORMAND DIRECT TERROIR | H16: Barquette en bois | I16: 250 g | J16: NON | K16: 5.5 % | L16: 3.95 | M16: 9.5 | N16: PROPOSÉ | O16: =IF(M16="","",M16-L16) | P16: =IF(OR(M16="",M16=0),"",(M16-L16)/M16) | Q16: =IF(OR(M16="",L16=0,L16=""),"",M16/L16) | R16: =IF(M16="","",M16*1.055)
A17: PROD-0025 | B17: Tuiles pâtissières 150 grs | C17: BISCUITERIE | D17: BISCUIT | E17: ESSENTIEL | F17: BISCUITERIE DE QUINEVILLE | G17: NORMAND DIRECT TERROIR | I17: 150 g | J17: NON | K17: 5.5 % | L17: 3.85 | M17: 9.2 | N17: PROPOSÉ | O17: =IF(M17="","",M17-L17) | P17: =IF(OR(M17="",M17=0),"",(M17-L17)/M17) | Q17: =IF(OR(M17="",L17=0,L17=""),"",M17/L17) | R17: =IF(M17="","",M17*1.055)
A18: PROD-0453 | B18: Pain D'épices Nature 250gr | C18: BISCUITERIE | D18: BISCUIT | E18: ESSENTIEL | F18: Rucher du bocage Virois | G18: NORMAND DIRECT TERROIR | H18: Barquette en bois | I18: 250 g | J18: NON | K18: 5.5 % | L18: 3.8 | M18: 9.1 | N18: PROPOSÉ | O18: =IF(M18="","",M18-L18) | P18: =IF(OR(M18="",M18=0),"",(M18-L18)/M18) | Q18: =IF(OR(M18="",L18=0,L18=""),"",M18/L18) | R18: =IF(M18="","",M18*1.055)
A19: PROD-0014 | B19: Croquenoisettes 180 grs | C19: BISCUITERIE | D19: BISCUIT | E19: ESSENTIEL | F19: BISCUITERIE DE QUINEVILLE | G19: NORMAND DIRECT TERROIR | I19: 180 g | J19: NON | K19: 5.5 % | L19: 3.73 | M19: 9 | N19: PROPOSÉ | O19: =IF(M19="","",M19-L19) | P19: =IF(OR(M19="",M19=0),"",(M19-L19)/M19) | Q19: =IF(OR(M19="",L19=0,L19=""),"",M19/L19) | R19: =IF(M19="","",M19*1.055)
A20: PROD-0024 | B20: Sablés Mamie 220 grs | C20: BISCUITERIE | D20: BISCUIT | E20: ESSENTIEL | F20: BISCUITERIE DE QUINEVILLE | G20: NORMAND DIRECT TERROIR | I20: 220 g | J20: NON | K20: 5.5 % | L20: 3.65 | M20: 8.8 | N20: PROPOSÉ | O20: =IF(M20="","",M20-L20) | P20: =IF(OR(M20="",M20=0),"",(M20-L20)/M20) | Q20: =IF(OR(M20="",L20=0,L20=""),"",M20/L20) | R20: =IF(M20="","",M20*1.055)
A21: PROD-0005 | B21: Boutons de la Manche 250 grs moins de 12 | C21: BISCUITERIE | D21: BISCUIT | E21: ESSENTIEL | F21: BISCUITERIE DE QUINEVILLE | G21: NORMAND DIRECT TERROIR | I21: 250 g | J21: NON | K21: 5.5 % | L21: 3.6 | M21: 8.6 | N21: PROPOSÉ | O21: =IF(M21="","",M21-L21) | P21: =IF(OR(M21="",M21=0),"",(M21-L21)/M21) | Q21: =IF(OR(M21="",L21=0,L21=""),"",M21/L21) | R21: =IF(M21="","",M21*1.055)
A22: PROD-0007 | B22: Cookies pépite de chocolat 220 grs | C22: BISCUITERIE | D22: BISCUIT | E22: ESSENTIEL | F22: BISCUITERIE DE QUINEVILLE | G22: NORMAND DIRECT TERROIR | I22: 220 g | J22: NON | K22: 5.5 % | L22: 3.6 | M22: 8.6 | N22: PROPOSÉ | O22: =IF(M22="","",M22-L22) | P22: =IF(OR(M22="",M22=0),"",(M22-L22)/M22) | Q22: =IF(OR(M22="",L22=0,L22=""),"",M22/L22) | R22: =IF(M22="","",M22*1.055)
A23: PROD-0021 | B23: Sablé éclats de caramel 180 grs | C23: BISCUITERIE | D23: BISCUIT | E23: ESSENTIEL | F23: BISCUITERIE DE QUINEVILLE | G23: NORMAND DIRECT TERROIR | I23: 180 g | J23: NON | K23: 5.5 % | L23: 3.56 | M23: 8.5 | N23: PROPOSÉ | O23: =IF(M23="","",M23-L23) | P23: =IF(OR(M23="",M23=0),"",(M23-L23)/M23) | Q23: =IF(OR(M23="",L23=0,L23=""),"",M23/L23) | R23: =IF(M23="","",M23*1.055)
A24: PROD-0016 | B24: Croquet Calvados 180 grs | C24: BISCUITERIE | D24: BISCUIT | E24: ESSENTIEL | F24: BISCUITERIE DE QUINEVILLE | G24: NORMAND DIRECT TERROIR | I24: 180 g | J24: INGREDIENT_ALCOOLISE | K24: 5.5 % | L24: 3.55 | M24: 8.5 | N24: PROPOSÉ | O24: =IF(M24="","",M24-L24) | P24: =IF(OR(M24="",M24=0),"",(M24-L24)/M24) | Q24: =IF(OR(M24="",L24=0,L24=""),"",M24/L24) | R24: =IF(M24="","",M24*1.055)
A25: PROD-0015 | B25: Croquentin 220 grs | C25: BISCUITERIE | D25: BISCUIT | E25: ESSENTIEL | F25: BISCUITERIE DE QUINEVILLE | G25: NORMAND DIRECT TERROIR | I25: 220 g | J25: NON | K25: 5.5 % | L25: 3.5 | M25: 8.4 | N25: PROPOSÉ | O25: =IF(M25="","",M25-L25) | P25: =IF(OR(M25="",M25=0),"",(M25-L25)/M25) | Q25: =IF(OR(M25="",L25=0,L25=""),"",M25/L25) | R25: =IF(M25="","",M25*1.055)
A26: PROD-0006 | B26: Boutons de la Manche 250 grs/ carton de 12 | C26: BISCUITERIE | D26: BISCUIT | E26: ESSENTIEL | F26: BISCUITERIE DE QUINEVILLE | G26: NORMAND DIRECT TERROIR | I26: 250 g | J26: NON | K26: 5.5 % | L26: 3.45 | M26: 8.3 | N26: PROPOSÉ | O26: =IF(M26="","",M26-L26) | P26: =IF(OR(M26="",M26=0),"",(M26-L26)/M26) | Q26: =IF(OR(M26="",L26=0,L26=""),"",M26/L26) | R26: =IF(M26="","",M26*1.055)
A27: PROD-0019 | B27: Pailles feuilletées au sucre 150 grs | C27: BISCUITERIE | D27: BISCUIT | E27: ESSENTIEL | F27: BISCUITERIE DE QUINEVILLE | G27: NORMAND DIRECT TERROIR | I27: 150 g | J27: NON | K27: 5.5 % | L27: 3.45 | M27: 8.3 | N27: PROPOSÉ | O27: =IF(M27="","",M27-L27) | P27: =IF(OR(M27="",M27=0),"",(M27-L27)/M27) | Q27: =IF(OR(M27="",L27=0,L27=""),"",M27/L27) | R27: =IF(M27="","",M27*1.055)
A28: PROD-0017 | B28: Financier sachet 180 grs | C28: BISCUITERIE | D28: BISCUIT | E28: ESSENTIEL | F28: BISCUITERIE DE QUINEVILLE | G28: NORMAND DIRECT TERROIR | I28: 180 g | J28: NON | K28: 5.5 % | L28: 3.25 | M28: 7.8 | N28: PROPOSÉ | O28: =IF(M28="","",M28-L28) | P28: =IF(OR(M28="",M28=0),"",(M28-L28)/M28) | Q28: =IF(OR(M28="",L28=0,L28=""),"",M28/L28) | R28: =IF(M28="","",M28*1.055)
A29: PROD-0026 | B29: Sablette mendiante chocolat 130 grs | C29: BISCUITERIE | D29: BISCUIT | E29: ESSENTIEL | F29: BISCUITERIE DE QUINEVILLE | G29: NORMAND DIRECT TERROIR | I29: 130 g | J29: NON | K29: 5.5 % | L29: 3 | M29: 7.2 | N29: PROPOSÉ | O29: =IF(M29="","",M29-L29) | P29: =IF(OR(M29="",M29=0),"",(M29-L29)/M29) | Q29: =IF(OR(M29="",L29=0,L29=""),"",M29/L29) | R29: =IF(M29="","",M29*1.055)
A30: PROD-0003 | B30: Palets Camembert du Cotentin pavot 100 grs | C30: BISCUITERIE | D30: BISCUIT | E30: ESSENTIEL | F30: BISCUITERIE DE QUINEVILLE | G30: NORMAND DIRECT TERROIR | I30: 100 g | J30: NON | K30: 5.5 % | L30: 2.5 | M30: 6.6 | N30: PROPOSÉ | O30: =IF(M30="","",M30-L30) | P30: =IF(OR(M30="",M30=0),"",(M30-L30)/M30) | Q30: =IF(OR(M30="",L30=0,L30=""),"",M30/L30) | R30: =IF(M30="","",M30*1.055)
... A35: PROD-0001 | B35: Apéro tomate/paprika 100 grs | C35: BISCUITERIE | D35: BISCUIT | E35: ESSENTIEL | F35: BISCUITERIE DE QUINEVILLE | G35: NORMAND DIRECT TERROIR | I35: 100 g | J35: NON | K35: 5.5 % | L35: 2.15 | M35: 5.7 | N35: PROPOSÉ | O35: =IF(M35="","",M35-L35) | P35: =IF(OR(M35="",M35=0),"",(M35-L35)/M35) | Q35: =IF(OR(M35="",L35=0,L35=""),"",M35/L35) | R35: =IF(M35="","",M35*1.055)
A36: PROD-0452 | B36: Pain D'épices Nature 100gr | C36: BISCUITERIE | D36: BISCUIT | E36: ESSENTIEL | F36: Rucher du bocage Virois | G36: NORMAND DIRECT TERROIR | H36: Barquette en bois | I36: 100 g | J36: NON | K36: À CONFIRMER | L36: 1.9 | M36: 5 | N36: PROPOSÉ | O36: =IF(M36="","",M36-L36) | P36: =IF(OR(M36="",M36=0),"",(M36-L36)/M36) | Q36: =IF(OR(M36="",L36=0,L36=""),"",M36/L36) | R36: =IF(M36="","","TVA à confirmer")
A37: PROD-0029 | B37: Tuiles chocolat noir et lacté 200gr | C37: BISCUITERIE | D37: BISCUIT | E37: SIGNATURE | F37: BISCUITERIE DE QUINEVILLE | G37: NORMAND DIRECT TERROIR | I37: 200 g | J37: NON | K37: 20 % | L37: 8.3 | M37: 18.3 | N37: PROPOSÉ | O37: =IF(M37="","",M37-L37) | P37: =IF(OR(M37="",M37=0),"",(M37-L37)/M37) | Q37: =IF(OR(M37="",L37=0,L37=""),"",M37/L37) | R37: =IF(M37="","",M37*1.2)
A38: PROD-0032 | B38: Grignotines amandes noisettes 200 grs | C38: BISCUITERIE | D38: BISCUIT | E38: SIGNATURE | F38: BISCUITERIE DE QUINEVILLE | G38: NORMAND DIRECT TERROIR | I38: 200 g | J38: NON | K38: 5.5 % | L38: 7.4 | M38: 17.8 | N38: PROPOSÉ | O38: =IF(M38="","",M38-L38) | P38: =IF(OR(M38="",M38=0),"",(M38-L38)/M38) | Q38: =IF(OR(M38="",L38=0,L38=""),"",M38/L38) | R38: =IF(M38="","",M38*1.055)
A39: PROD-0284 | B39: BISCUITS 150g CAEN Mairie | C39: BISCUITERIE | D39: BISCUIT | E39: SIGNATURE | F39: BALADES NORMANDES | G39: NORMAND DIRECT TERROIR | H39: Boîte fer | I39: 150 g | J39: NON | K39: 5.5 % | L39: 7.31 | M39: 17.5 | N39: PROPOSÉ | O39: =IF(M39="","",M39-L39) | P39: =IF(OR(M39="",M39=0),"",(M39-L39)/M39) | Q39: =IF(OR(M39="",L39=0,L39=""),"",M39/L39) | R39: =IF(M39="","",M39*1.055)
A40: PROD-0285 | B40: BISCUITS 150g Ouistreham B-LEC | C40: BISCUITERIE | D40: BISCUIT | E40: SIGNATURE | F40: BALADES NORMANDES | G40: NORMAND DIRECT TERROIR | H40: Boîte fer | I40: 150 g | J40: NON | K40: 5.5 % | L40: 7.31 | M40: 17.5 | N40: PROPOSÉ | O40: =IF(M40="","",M40-L40) | P40: =IF(OR(M40="",M40=0),"",(M40-L40)/M40) | Q40: =IF(OR(M40="",L40=0,L40=""),"",M40/L40) | R40: =IF(M40="","",M40*1.055)
A41: PROD-0286 | B41: BISCUITS 150g Caen Château B-LEC | C41: BISCUITERIE | D41: BISCUIT | E41: SIGNATURE | F41: BALADES NORMANDES | G41: NORMAND DIRECT TERROIR | H41: Boîte fer | I41: 150 g | J41: NON | K41: 5.5 % | L41: 7.31 | M41: 17.5 | N41: PROPOSÉ | O41: =IF(M41="","",M41-L41) | P41: =IF(OR(M41="",M41=0),"",(M41-L41)/M41) | Q41: =IF(OR(M41="",L41=0,L41=""),"",M41/L41) | R41: =IF(M41="","",M41*1.055)
A42: PROD-0287 | B42: BISCUITS 150g Caen cœur de ville Aquarelle | C42: BISCUITERIE | D42: BISCUIT | E42: SIGNATURE | F42: BALADES NORMANDES | G42: NORMAND DIRECT TERROIR | H42: Boîte fer | I42: 150 g | J42: NON | K42: 5.5 % | L42: 7.31 | M42: 17.5 | N42: PROPOSÉ | O42: =IF(M42="","",M42-L42) | P42: =IF(OR(M42="",M42=0),"",(M42-L42)/M42) | Q42: =IF(OR(M42="",L42=0,L42=""),"",M42/L42) | R42: =IF(M42="","",M42*1.055)
A43: PROD-0288 | B43: Biscuits 150g Pays D'Auge Aquarelle | C43: BISCUITERIE | D43: BISCUIT | E43: SIGNATURE | F43: BALADES NORMANDES | G43: NORMAND DIRECT TERROIR | H43: Boîte fer | I43: 150 g | J43: NON | K43: 5.5 % | L43: 7.31 | M43: 17.5 | N43: PROPOSÉ | O43: =IF(M43="","",M43-L43) | P43: =IF(OR(M43="",M43=0),"",(M43-L43)/M43) | Q43: =IF(OR(M43="",L43=0,L43=""),"",M43/L43) | R43: =IF(M43="","",M43*1.055)
A44: PROD-0289 | B44: Biscuits 150g Cambremer Aquarelle | C44: BISCUITERIE | D44: BISCUIT | E44: SIGNATURE | F44: BALADES NORMANDES | G44: NORMAND DIRECT TERROIR | H44: Boîte fer | I44: 150 g | J44: NON | K44: 5.5 % | L44: 7.31 | M44: 17.5 | N44: PROPOSÉ | O44: =IF(M44="","",M44-L44) | P44: =IF(OR(M44="",M44=0),"",(M44-L44)/M44) | Q44: =IF(OR(M44="",L44=0,L44=""),"",M44/L44) | R44: =IF(M44="","",M44*1.055)
...

Sheet Suivi
B1: Où en est la saisie
B3: Produits au total | C3: =COUNTA('Prix de vente'!A2:A703)
B4: Prix renseignés (proposés ou validés) | C4: =COUNT('Prix de vente'!M2:M703)
B5: Reste à saisir | C5: =C3-C4
B6: Avancement | C6: =IF(C3=0,0,C4/C3)
B7: Prix VALIDÉS par vous | C7: =COUNTIF('Prix de vente'!N2:N703,"VALIDÉ")
B8: Retenus au catalogue de saison | C8: =COUNTIF('Prix de vente'!S2:S703,"OUI")
B9: dont prix saisi | C9: =COUNTIFS('Prix de vente'!S2:S703,"OUI",'Prix de vente'!M2:M703,">0")
B10: reste à saisir sur la saison | C10: =C8-C9
B12: Contrôles
B14: Prix de vente ≤ prix d'achat | C14: =SUMPRODUCT(--('Prix de vente'!M2:M703<>""),--('Prix de vente'!M2:M703<='Prix de vente'!L2:L703))
B15: Taux de marge sous 30 % | C15: =SUMPRODUCT(--('Prix de vente'!M2:M703>0),--('Prix de vente'!P2:P703<0.3))
B16: TVA à confirmer | C16: =COUNTIF('Prix de vente'!K2:K703,"À CONFIRMER")
B17: dont déjà retenus en saison | C17: =COUNTIFS('Prix de vente'!K2:K703,"À CONFIRMER",'Prix de vente'!S2:S703,"OUI")
B19: Marge moyenne sur ce qui est saisi
B21: Taux de marge moyen | C21: =IFERROR(AVERAGEIF('Prix de vente'!M2:M703,">0",'Prix de vente'!P2:P703),"—")
B22: Coefficient moyen | C22: =IFERROR(AVERAGEIF('Prix de vente'!M2:M703,">0",'Prix de vente'!Q2:Q703),"—")
B24: Ces contrôles se mettent à jour tout seuls pendant la saisie. Une valeur non nulle sur les deux premiers demande une vérification.
